<?xml version="1.0" encoding="utf-8"?>
<!-- This URDF was automatically created by SolidWorks to URDF Exporter! Originally created by Stephen Brawner (brawner@gmail.com) 
     Commit Version: 1.6.1-9-gee910b2-dirty  Build Version: 1.6.9034.11310
     For more information, please see http://wiki.ros.org/sw_urdf_exporter -->
<robot
  name="Whole BODY URDF SET UP">
  <link
    name="base_link">
    <inertial>
      <origin
        xyz="-3.79196909459318E-12 -4.73285478137411E-11 1.22993156309946E-05"
        rpy="0 0 0" />
      <mass
        value="0.0712944231487941" />
      <inertia
        ixx="0.000399097163214721"
        ixy="-6.42255535002429E-13"
        ixz="-1.71654257053057E-16"
        iyy="3.100773358623E-05"
        iyz="-3.3241040190076E-15"
        izz="0.000378318474974681" />
    </inertial>
    <visual>
      <origin
        xyz="0 0 0"
        rpy="0 0 0" />
      <geometry>
        <mesh
          filename="package://Whole BODY URDF SET UP/meshes/base_link.STL" />
      </geometry>
      <material
        name="">
        <color
          rgba="0.792156862745098 0.819607843137255 0.933333333333333 1" />
      </material>
    </visual>
    <collision>
      <origin
        xyz="0 0 0"
        rpy="0 0 0" />
      <geometry>
        <mesh
          filename="package://Whole BODY URDF SET UP/meshes/base_link.STL" />
      </geometry>
    </collision>
  </link>
  <link
    name="Front_Hip">
    <inertial>
      <origin
        xyz="-0.0542406994149277 0.0322730422705062 3.74012382937583E-05"
        rpy="0 0 0" />
      <mass
        value="0.121414931103108" />
      <inertia
        ixx="0.000104658493106656"
        ixy="-5.87910724622098E-13"
        ixz="-4.97582005480662E-12"
        iyy="9.3656901814943E-05"
        iyz="2.09107841059153E-08"
        izz="0.000157485606415984" />
    </inertial>
    <visual>
      <origin
        xyz="0 0 0"
        rpy="0 0 0" />
      <geometry>
        <mesh
          filename="package://Whole BODY URDF SET UP/meshes/Front_Hip.STL" />
      </geometry>
      <material
        name="">
        <color
          rgba="0.792156862745098 0.819607843137255 0.933333333333333 1" />
      </material>
    </visual>
    <collision>
      <origin
        xyz="0 0 0"
        rpy="0 0 0" />
      <geometry>
        <mesh
          filename="package://Whole BODY URDF SET UP/meshes/Front_Hip.STL" />
      </geometry>
    </collision>
  </link>
  <joint
    name="Front_Hip"
    type="fixed">
    <origin
      xyz="0.0542407007709616 0.1149985 5.35317635531158E-05"
      rpy="0 0 0" />
    <parent
      link="base_link" />
    <child
      link="Front_Hip" />
    <axis
      xyz="0 0 0" />
  </joint>
  <link
    name="Front_Left_Shoulder">
    <inertial>
      <origin
        xyz="0.0137739851795441 -0.0125083167030698 -0.0391386009814933"
        rpy="0 0 0" />
      <mass
        value="0.140436940047647" />
      <inertia
        ixx="2.80379795093138E-05"
        ixy="5.40046079082896E-07"
        ixz="5.83190778717265E-09"
        iyy="4.80687439403981E-05"
        iyz="1.13010403668755E-07"
        izz="4.46905233653811E-05" />
    </inertial>
    <visual>
      <origin
        xyz="0 0 0"
        rpy="0 0 0" />
      <geometry>
        <mesh
          filename="package://Whole BODY URDF SET UP/meshes/Front_Left_Shoulder.STL" />
      </geometry>
      <material
        name="">
        <color
          rgba="0.752941176470588 0.752941176470588 0.752941176470588 1" />
      </material>
    </visual>
    <collision>
      <origin
        xyz="0 0 0"
        rpy="0 0 0" />
      <geometry>
        <mesh
          filename="package://Whole BODY URDF SET UP/meshes/Front_Left_Shoulder.STL" />
      </geometry>
    </collision>
  </link>
  <joint
    name="Front_Left_Shoulder"
    type="revolute">
    <origin
      xyz="-0.118561401541924 0 0"
      rpy="1.5707963267949 -0.0365489253746626 0" />
    <parent
      link="Front_Hip" />
    <child
      link="Front_Left_Shoulder" />
    <axis
      xyz="0 0 1" />
    <limit
      lower="-1.57"
      upper="1.57"
      effort="0"
      velocity="0" />
  </joint>
  <link
    name="Front_Left_Upper_Leg">
    <inertial>
      <origin
        xyz="-0.0138284683520782 -0.0347803760409055 0.0524397996972768"
        rpy="0 0 0" />
      <mass
        value="0.0622185374309281" />
      <inertia
        ixx="3.95026604801634E-05"
        ixy="3.21197098204208E-06"
        ixz="-4.52317416236056E-06"
        iyy="3.18332810578734E-05"
        iyz="1.54040416736055E-05"
        izz="2.00120493351569E-05" />
    </inertial>
    <visual>
      <origin
        xyz="0 0 0"
        rpy="0 0 0" />
      <geometry>
        <mesh
          filename="package://Whole BODY URDF SET UP/meshes/Front_Left_Upper_Leg.STL" />
      </geometry>
      <material
        name="">
        <color
          rgba="0.752941176470588 0.752941176470588 0.752941176470588 1" />
      </material>
    </visual>
    <collision>
      <origin
        xyz="0 0 0"
        rpy="0 0 0" />
      <geometry>
        <mesh
          filename="package://Whole BODY URDF SET UP/meshes/Front_Left_Upper_Leg.STL" />
      </geometry>
    </collision>
  </link>
  <joint
    name="Front_Left_Upper_Leg"
    type="revolute">
    <origin
      xyz="-0.00185531578486946 -0.0359521599259129 -0.0287921500156247"
      rpy="0.940540322874895 -0.0416664486626156 -0.0211815707953396" />
    <parent
      link="Front_Left_Shoulder" />
    <child
      link="Front_Left_Upper_Leg" />
    <axis
      xyz="0.998671109053135 -0.0515365495797057 0" />
    <limit
      lower="-1.57"
      upper="1.57"
      effort="0"
      velocity="0" />
  </joint>
  <link
    name="Front_Left_Lower_Leg">
    <inertial>
      <origin
        xyz="-0.0136277736994216 -0.0505339035503838 -0.0279236330848666"
        rpy="0 0 0" />
      <mass
        value="0.0155256621613376" />
      <inertia
        ixx="2.38562608052699E-05"
        ixy="-8.45654826936085E-07"
        ixz="-4.48322423480095E-07"
        iyy="5.96509335753058E-06"
        iyz="-9.5310841114569E-06"
        izz="1.82031583320902E-05" />
    </inertial>
    <visual>
      <origin
        xyz="0 0 0"
        rpy="0 0 0" />
      <geometry>
        <mesh
          filename="package://Whole BODY URDF SET UP/meshes/Front_Left_Lower_Leg.STL" />
      </geometry>
      <material
        name="">
        <color
          rgba="0.752941176470588 0.752941176470588 0.752941176470588 1" />
      </material>
    </visual>
    <collision>
      <origin
        xyz="0 0 0"
        rpy="0 0 0" />
      <geometry>
        <mesh
          filename="package://Whole BODY URDF SET UP/meshes/Front_Left_Lower_Leg.STL" />
      </geometry>
    </collision>
  </link>
  <joint
    name="Front_Left_Lower_Leg"
    type="revolute">
    <origin
      xyz="-0.0239845511436166 -0.0511939313025561 0.0774627196076526"
      rpy="-1.41646272232564 0.0509476316630302 -0.0436370237871092" />
    <parent
      link="Front_Left_Upper_Leg" />
    <child
      link="Front_Left_Lower_Leg" />
    <axis
      xyz="0.998671109053135 -0.0515365495797045 0" />
    <limit
      lower="-1.57"
      upper="1.57"
      effort="0"
      velocity="0" />
  </joint>
  <link
    name="Front_Right_Shoulder">
    <inertial>
      <origin
        xyz="-0.00461374227477766 -0.0147975561386528 -0.0391253002509455"
        rpy="0 0 0" />
      <mass
        value="0.107869096375755" />
      <inertia
        ixx="2.22394596492883E-05"
        ixy="4.94574385861689E-07"
        ixz="-2.34396356728712E-07"
        iyy="3.46102501709838E-05"
        iyz="-4.77724670579523E-08"
        izz="2.85445263842194E-05" />
    </inertial>
    <visual>
      <origin
        xyz="0 0 0"
        rpy="0 0 0" />
      <geometry>
        <mesh
          filename="package://Whole BODY URDF SET UP/meshes/Front_Right_Shoulder.STL" />
      </geometry>
      <material
        name="">
        <color
          rgba="0.752941176470588 0.752941176470588 0.752941176470588 1" />
      </material>
    </visual>
    <collision>
      <origin
        xyz="0 0 0"
        rpy="0 0 0" />
      <geometry>
        <mesh
          filename="package://Whole BODY URDF SET UP/meshes/Front_Right_Shoulder.STL" />
      </geometry>
    </collision>
  </link>
  <joint
    name="Front_Right_Shoulder"
    type="revolute">
    <origin
      xyz="0.01 0 0"
      rpy="1.5707963267949 0 0" />
    <parent
      link="Front_Hip" />
    <child
      link="Front_Right_Shoulder" />
    <axis
      xyz="0 0 1" />
    <limit
      lower="-1.57"
      upper="1.57"
      effort="0"
      velocity="0" />
  </joint>
  <link
    name="Front_Right_Upper_Leg">
    <inertial>
      <origin
        xyz="0.0145550029225172 -0.0502252403253611 0.025931874412354"
        rpy="0 0 0" />
      <mass
        value="0.0933622190352868" />
      <inertia
        ixx="7.29830992475442E-05"
        ixy="-1.14286741887544E-05"
        ixz="5.90010671510385E-06"
        iyy="2.77722077001298E-05"
        iyz="2.526024805234E-05"
        izz="6.36533679052227E-05" />
    </inertial>
    <visual>
      <origin
        xyz="0 0 0"
        rpy="0 0 0" />
      <geometry>
        <mesh
          filename="package://Whole BODY URDF SET UP/meshes/Front_Right_Upper_Leg.STL" />
      </geometry>
      <material
        name="">
        <color
          rgba="0.752941176470588 0.752941176470588 0.752941176470588 1" />
      </material>
    </visual>
    <collision>
      <origin
        xyz="0 0 0"
        rpy="0 0 0" />
      <geometry>
        <mesh
          filename="package://Whole BODY URDF SET UP/meshes/Front_Right_Upper_Leg.STL" />
      </geometry>
    </collision>
  </link>
  <joint
    name="Front_Right_Upper_Leg"
    type="revolute">
    <origin
      xyz="0 -0.0359999999999964 -0.0290450000000011"
      rpy="0.449742756146675 0 0" />
    <parent
      link="Front_Right_Shoulder" />
    <child
      link="Front_Right_Upper_Leg" />
    <axis
      xyz="1 0 0" />
    <limit
      lower="-1.57"
      upper="1.57"
      effort="0"
      velocity="0" />
  </joint>
  <link
    name="Front_Right_Lower_Leg">
    <inertial>
      <origin
        xyz="0.00576780968735226 -0.0400146670662195 -0.03842906672573"
        rpy="0 0 0" />
      <mass
        value="0.01631288240346" />
      <inertia
        ixx="2.39312087583388E-05"
        ixy="-6.54525511951302E-08"
        ixz="-6.28595038448721E-08"
        iyy="1.16247328034003E-05"
        iyz="-1.1336330395926E-05"
        izz="1.25417009886083E-05" />
    </inertial>
    <visual>
      <origin
        xyz="0 0 0"
        rpy="0 0 0" />
      <geometry>
        <mesh
          filename="package://Whole BODY URDF SET UP/meshes/Front_Right_Lower_Leg.STL" />
      </geometry>
      <material
        name="">
        <color
          rgba="0.752941176470588 0.752941176470588 0.752941176470588 1" />
      </material>
    </visual>
    <collision>
      <origin
        xyz="0 0 0"
        rpy="0 0 0" />
      <geometry>
        <mesh
          filename="package://Whole BODY URDF SET UP/meshes/Front_Right_Lower_Leg.STL" />
      </geometry>
    </collision>
  </link>
  <joint
    name="Front_Right_Lower_Leg"
    type="revolute">
    <origin
      xyz="0.0265392992290382 -0.0830793712108725 0.0428960147240504"
      rpy="-1.19874044905665 0 0" />
    <parent
      link="Front_Right_Upper_Leg" />
    <child
      link="Front_Right_Lower_Leg" />
    <axis
      xyz="1 0 0" />
    <limit
      lower="-1.57"
      upper="1.57"
      effort="0"
      velocity="0" />
  </joint>
  <link
    name="Back_Hip">
    <inertial>
      <origin
        xyz="-0.0542406994149277 0.0322730422705062 3.74012382937617E-05"
        rpy="0 0 0" />
      <mass
        value="0.121414931103108" />
      <inertia
        ixx="0.000104658493106656"
        ixy="-5.87910763770902E-13"
        ixz="-4.9758199155276E-12"
        iyy="9.36569018149431E-05"
        iyz="2.09107841058601E-08"
        izz="0.000157485606415984" />
    </inertial>
    <visual>
      <origin
        xyz="0 0 0"
        rpy="0 0 0" />
      <geometry>
        <mesh
          filename="package://Whole BODY URDF SET UP/meshes/Back_Hip.STL" />
      </geometry>
      <material
        name="">
        <color
          rgba="0.792156862745098 0.819607843137255 0.933333333333333 1" />
      </material>
    </visual>
    <collision>
      <origin
        xyz="0 0 0"
        rpy="0 0 0" />
      <geometry>
        <mesh
          filename="package://Whole BODY URDF SET UP/meshes/Back_Hip.STL" />
      </geometry>
    </collision>
  </link>
  <joint
    name="Back_Hip"
    type="fixed">
    <origin
      xyz="0.0542407007709615 -0.1897985 5.35317635530875E-05"
      rpy="0 0 0" />
    <parent
      link="base_link" />
    <child
      link="Back_Hip" />
    <axis
      xyz="0 0 0" />
  </joint>
  <link
    name="Back_Right_Shoulder">
    <inertial>
      <origin
        xyz="-0.00461374227477765 -0.0147975561386528 -0.0391253002509454"
        rpy="0 0 0" />
      <mass
        value="0.107869096375755" />
      <inertia
        ixx="2.22394596492883E-05"
        ixy="4.9457438586169E-07"
        ixz="-2.34396356728709E-07"
        iyy="3.46102501709838E-05"
        iyz="-4.77724670579598E-08"
        izz="2.85445263842194E-05" />
    </inertial>
    <visual>
      <origin
        xyz="0 0 0"
        rpy="0 0 0" />
      <geometry>
        <mesh
          filename="package://Whole BODY URDF SET UP/meshes/Back_Right_Shoulder.STL" />
      </geometry>
      <material
        name="">
        <color
          rgba="0.752941176470588 0.752941176470588 0.752941176470588 1" />
      </material>
    </visual>
    <collision>
      <origin
        xyz="0 0 0"
        rpy="0 0 0" />
      <geometry>
        <mesh
          filename="package://Whole BODY URDF SET UP/meshes/Back_Right_Shoulder.STL" />
      </geometry>
    </collision>
  </link>
  <joint
    name="Back_Right_Shoulder"
    type="revolute">
    <origin
      xyz="0.01 0 0"
      rpy="1.5707963267949 0 0" />
    <parent
      link="Back_Hip" />
    <child
      link="Back_Right_Shoulder" />
    <axis
      xyz="0 0 1" />
    <limit
      lower="-1.57"
      upper="1.57"
      effort="0"
      velocity="0" />
  </joint>
  <link
    name="Back_Right_Upper_Leg">
    <inertial>
      <origin
        xyz="0.0145550053982749 -0.0502252420931474 0.0259318753093942"
        rpy="0 0 0" />
      <mass
        value="0.0933621516301469" />
      <inertia
        ixx="7.29830746154553E-05"
        ixy="-1.14286631416169E-05"
        ixz="5.90010372776624E-06"
        iyy="2.77721811223266E-05"
        iyz="2.52602439633051E-05"
        izz="6.36533220616484E-05" />
    </inertial>
    <visual>
      <origin
        xyz="0 0 0"
        rpy="0 0 0" />
      <geometry>
        <mesh
          filename="package://Whole BODY URDF SET UP/meshes/Back_Right_Upper_Leg.STL" />
      </geometry>
      <material
        name="">
        <color
          rgba="0.752941176470588 0.752941176470588 0.752941176470588 1" />
      </material>
    </visual>
    <collision>
      <origin
        xyz="0 0 0"
        rpy="0 0 0" />
      <geometry>
        <mesh
          filename="package://Whole BODY URDF SET UP/meshes/Back_Right_Upper_Leg.STL" />
      </geometry>
    </collision>
  </link>
  <joint
    name="Back_Right_Upper_Leg"
    type="revolute">
    <origin
      xyz="0 -0.0360000000000002 -0.0290449999999998"
      rpy="0.475650962623188 0 0" />
    <parent
      link="Back_Right_Shoulder" />
    <child
      link="Back_Right_Upper_Leg" />
    <axis
      xyz="1 0 0" />
    <limit
      lower="-1.57"
      upper="1.57"
      effort="0"
      velocity="0" />
  </joint>
  <link
    name="Back_Right_Lower_Leg">
    <inertial>
      <origin
        xyz="0.00576780968178837 -0.0400146670657065 -0.0384290667120226"
        rpy="0 0 0" />
      <mass
        value="0.0163128824062683" />
      <inertia
        ixx="2.39312087567438E-05"
        ixy="-6.54525438879936E-08"
        ixz="-6.28594972194673E-08"
        iyy="1.16247328025623E-05"
        iyz="-1.13363303950864E-05"
        izz="1.2541700987751E-05" />
    </inertial>
    <visual>
      <origin
        xyz="0 0 0"
        rpy="0 0 0" />
      <geometry>
        <mesh
          filename="package://Whole BODY URDF SET UP/meshes/Back_Right_Lower_Leg.STL" />
      </geometry>
      <material
        name="">
        <color
          rgba="0.752941176470588 0.752941176470588 0.752941176470588 1" />
      </material>
    </visual>
    <collision>
      <origin
        xyz="0 0 0"
        rpy="0 0 0" />
      <geometry>
        <mesh
          filename="package://Whole BODY URDF SET UP/meshes/Back_Right_Lower_Leg.STL" />
      </geometry>
    </collision>
  </link>
  <joint
    name="Back_Right_Lower_Leg"
    type="revolute">
    <origin
      xyz="0.0265392992290382 -0.0830793712108724 0.0428960147240505"
      rpy="-1.20853606323344 0 0" />
    <parent
      link="Back_Right_Upper_Leg" />
    <child
      link="Back_Right_Lower_Leg" />
    <axis
      xyz="1 0 0" />
    <limit
      lower="-1.57"
      upper="1.57"
      effort="0"
      velocity="0" />
  </joint>
  <link
    name="Back_Left_Shoulder">
    <inertial>
      <origin
        xyz="0.0127590396351129 -0.013542066416756 -0.0391386009725268"
        rpy="0 0 0" />
      <mass
        value="0.140436940239167" />
      <inertia
        ixx="2.8243014244986E-05"
        ixy="2.08724991635799E-06"
        ixz="1.46068585646496E-08"
        iyy="4.78637093003705E-05"
        iyz="1.12214075389823E-07"
        izz="4.46905233935649E-05" />
    </inertial>
    <visual>
      <origin
        xyz="0 0 0"
        rpy="0 0 0" />
      <geometry>
        <mesh
          filename="package://Whole BODY URDF SET UP/meshes/Back_Left_Shoulder.STL" />
      </geometry>
      <material
        name="">
        <color
          rgba="0.752941176470588 0.752941176470588 0.752941176470588 1" />
      </material>
    </visual>
    <collision>
      <origin
        xyz="0 0 0"
        rpy="0 0 0" />
      <geometry>
        <mesh
          filename="package://Whole BODY URDF SET UP/meshes/Back_Left_Shoulder.STL" />
      </geometry>
    </collision>
  </link>
  <joint
    name="Back_Left_Shoulder"
    type="revolute">
    <origin
      xyz="-0.118561401541923 0 0"
      rpy="1.5707963267949 -0.0348277893882829 0" />
    <parent
      link="Back_Hip" />
    <child
      link="Back_Left_Shoulder" />
    <axis
      xyz="0 0 1" />
    <limit
      lower="-1.57"
      upper="1.57"
      effort="0"
      velocity="0" />
  </joint>
  <link
    name="Back_Left_Upper_Leg">
    <inertial>
      <origin
        xyz="-0.0214717435366657 -0.0336927352823517 0.0514158375828852"
        rpy="0 0 0" />
      <mass
        value="0.0622185882062138" />
      <inertia
        ixx="4.01805826515789E-05"
        ixy="1.84404538285222E-06"
        ixz="-2.5538347752028E-06"
        iyy="3.17158653112572E-05"
        iyz="1.56818019391028E-05"
        izz="1.94515615002159E-05" />
    </inertial>
    <visual>
      <origin
        xyz="0 0 0"
        rpy="0 0 0" />
      <geometry>
        <mesh
          filename="package://Whole BODY URDF SET UP/meshes/Back_Left_Upper_Leg.STL" />
      </geometry>
      <material
        name="">
        <color
          rgba="0.752941176470588 0.752941176470588 0.752941176470588 1" />
      </material>
    </visual>
    <collision>
      <origin
        xyz="0 0 0"
        rpy="0 0 0" />
      <geometry>
        <mesh
          filename="package://Whole BODY URDF SET UP/meshes/Back_Left_Upper_Leg.STL" />
      </geometry>
    </collision>
  </link>
  <joint
    name="Back_Left_Upper_Leg"
    type="revolute">
    <origin
      xyz="-0.00185531578486944 -0.0359521599259134 -0.0287921500156243"
      rpy="0.975683784629328 -0.0427074689558667 -0.0226638793301015" />
    <parent
      link="Back_Left_Shoulder" />
    <child
      link="Back_Left_Upper_Leg" />
    <axis
      xyz="0.998671109053135 -0.0515365495797065 0" />
    <limit
      lower="-1.57"
      upper="1.57"
      effort="0"
      velocity="0" />
  </joint>
  <link
    name="Back_Left_Lower_Leg">
    <inertial>
      <origin
        xyz="-0.0277861203569904 -0.04705867304066 -0.0265100084577737"
        rpy="0 0 0" />
      <mass
        value="0.0155256835027543" />
      <inertia
        ixx="2.35685073782154E-05"
        ixy="-2.40477099117039E-06"
        ixz="-1.30532111716224E-06"
        iyy="6.22559991503217E-06"
        iyz="-9.43470924733843E-06"
        izz="1.82311003328971E-05" />
    </inertial>
    <visual>
      <origin
        xyz="0 0 0"
        rpy="0 0 0" />
      <geometry>
        <mesh
          filename="package://Whole BODY URDF SET UP/meshes/Back_Left_Lower_Leg.STL" />
      </geometry>
      <material
        name="">
        <color
          rgba="0.752941176470588 0.752941176470588 0.752941176470588 1" />
      </material>
    </visual>
    <collision>
      <origin
        xyz="0 0 0"
        rpy="0 0 0" />
      <geometry>
        <mesh
          filename="package://Whole BODY URDF SET UP/meshes/Back_Left_Lower_Leg.STL" />
      </geometry>
    </collision>
  </link>
  <joint
    name="Back_Left_Lower_Leg"
    type="revolute">
    <origin
      xyz="-0.0241773638448891 -0.0511839811785878 0.0774627196076527"
      rpy="-1.45230650530627 0.051198504725547 -0.0454670754420785" />
    <parent
      link="Back_Left_Upper_Leg" />
    <child
      link="Back_Left_Lower_Leg" />
    <axis
      xyz="0.998671109053135 -0.0515365495797041 0" />
    <limit
      lower="-1.57"
      upper="1.57"
      effort="0"
      velocity="0" />
  </joint>
</robot>